Workbook

Sheet ETFs
A1: Name | B1: Ticker | C1: Fund Name | D1: Last Update | E1: Last Price | F1: 1d% | G1: Net Change | H1: Open | I1: Lo | J1: Hi | K1: Prev Cls | M1: 52W Lo | N1: 52W Hi | O1: Volume | P1: Avg Volume | Q1: Sector/Strategy | R1: Sub-Sector | S1: Fund Family | T1: Expense Ratio (net) | U1: Market Cap | V1: Total Assets (AUM) | W1: Net Assets | X1: 1 Yr % Change | Y1: Inception Date | Z1: NAV | AA1: PE Ratio (TTM) | AB1: Yield | AC1: Avg. Volume | AD1: Beta (5Y Monthly) | AE1: YTD Return | AF1: 1-Year Return | AG1: 3-Year Return | AH1: Shares Outstanding | AI1: Avg Volume (30d) | AJ1: Avg $ Volume (Est) | AK1: Expense Ratio | AL1: 52 Week High | AM1: 52 Week Low | AN1: Liquidity Rating | AO1: FX | AP1: Exchange | AQ1: Exh Abbr | AR1: Type
A2: ABXB | B2: ABXB | C2: Abacus Flexible Bond Leaders ETF | D2: {=_FV(A2,"Last trade time",TRUE)} -> #VALUE! | E2: {=_FV(A2,"Price")} -> #VALUE! | F2: {=_FV(A2,"Change (%)",TRUE)} -> #VALUE! | G2: {=_FV(A2,"Change")} -> #VALUE! | H2: {=_FV(A2,"Open")} -> #VALUE! | I2: {=_FV(A2,"Low")} -> #VALUE! | J2: {=_FV(A2,"High")} -> #VALUE! | K2: {=_FV(A2,"Previous close",TRUE)} -> #VALUE! | M2: {=_FV(A2,"52 week low",TRUE)} -> #VALUE! | N2: {=_FV(A2,"52 week high",TRUE)} -> #VALUE! | O2: {=_FV(A2,"Volume")} -> #VALUE! | P2: {=_FV(A2,"Volume average",TRUE)} -> #VALUE! | Q2: Fixed Income | T2: {=_FV(A2,"Expense ratio",TRUE)} -> #VALUE! | U2: {=_FV(A2,"Market cap",TRUE)} -> #VALUE! | X2: -6.18% | Z2: 19.51 | AC2: 841 | AE2: 3.438108 | AF2: 6.8381539 | AI2: 841 | AJ2: 16416.32 | AL2: 21.883 | AM2: 17.11 | AN2: Low | AO2: {=_FV(A2,"Currency")} -> #VALUE! | AP2: {=_FV(A2,"Exchange")} -> #VALUE! | AQ2: {=_FV(A2,"Exchange abbreviation",TRUE)} -> #VALUE! | AR2: {=_FV(A2,"Instrument type",TRUE)} -> #VALUE!
A3: NXTI | B3: NXTI | C3: Simplify Exchange Traded Funds Simplify Next Intangible Core I | D3: {=_FV(A3,"Last trade time",TRUE)} -> #VALUE! | E3: {=_FV(A3,"Price")} -> #VALUE! | F3: {=_FV(A3,"Change (%)",TRUE)} -> #VALUE! | G3: {=_FV(A3,"Change")} -> #VALUE! | H3: {=_FV(A3,"Open")} -> #VALUE! | I3: {=_FV(A3,"Low")} -> #VALUE! | J3: {=_FV(A3,"High")} -> #VALUE! | K3: {=_FV(A3,"Previous close",TRUE)} -> #VALUE! | M3: {=_FV(A3,"52 week low",TRUE)} -> #VALUE! | N3: {=_FV(A3,"52 week high",TRUE)} -> #VALUE! | O3: {=_FV(A3,"Volume")} -> #VALUE! | P3: {=_FV(A3,"Volume average",TRUE)} -> #VALUE! | Q3: Large Blend | S3: Simplify Asset Management | T3: {=_FV(A3,"Expense ratio",TRUE)} -> #VALUE! | U3: {=_FV(A3,"Market cap",TRUE)} -> #VALUE! | V3: 1494565 | W3: 1494565 | Y3: 2024-04-14 | Z3: 30.4136 | AA3: 31.761068 | AB3: 0.0364 | AC3: 1003 | AE3: 8.4555618 | AF3: 23.769972 | AI3: 1003 | AJ3: 30506.145 | AL3: 31.04 | AM3: 24.653 | AN3: Low | AO3: {=_FV(A3,"Currency")} -> #VALUE! | AP3: {=_FV(A3,"Exchange")} -> #VALUE! | AQ3: {=_FV(A3,"Exchange abbreviation",TRUE)} -> #VALUE! | AR3: {=_FV(A3,"Instrument type",TRUE)} -> #VALUE!
A4: OPPE | B4: OPPE | C4: WisdomTree European Opportunities Fund | D4: {=_FV(A4,"Last trade time",TRUE)} -> #VALUE! | E4: {=_FV(A4,"Price")} -> #VALUE! | F4: {=_FV(A4,"Change (%)",TRUE)} -> #VALUE! | G4: {=_FV(A4,"Change")} -> #VALUE! | H4: {=_FV(A4,"Open")} -> #VALUE! | I4: {=_FV(A4,"Low")} -> #VALUE! | J4: {=_FV(A4,"High")} -> #VALUE! | K4: {=_FV(A4,"Previous close",TRUE)} -> #VALUE! | M4: {=_FV(A4,"52 week low",TRUE)} -> #VALUE! | N4: {=_FV(A4,"52 week high",TRUE)} -> #VALUE! | O4: {=_FV(A4,"Volume")} -> #VALUE! | P4: {=_FV(A4,"Volume average",TRUE)} -> #VALUE! | Q4: Europe Stock | S4: WisdomTree | T4: {=_FV(A4,"Expense ratio",TRUE)} -> #VALUE! | U4: {=_FV(A4,"Market cap",TRUE)} -> #VALUE! | V4: 129346408 | W4: 129346408 | Y4: 2015-03-03 | Z4: 46.522 | AA4: 11.491941 | AB4: 0.0328 | AC4: 17476 | AE4: 22.404768 | AF4: 19.481549 | AI4: 17476 | AJ4: 816786.3 | AL4: 46.89 | AM4: 35.84 | AN4: Low | AO4: {=_FV(A4,"Currency")} -> #VALUE! | AP4: {=_FV(A4,"Exchange")} -> #VALUE! | AQ4: {=_FV(A4,"Exchange abbreviation",TRUE)} -> #VALUE! | AR4: {=_FV(A4,"Instrument type",TRUE)} -> #VALUE!
A5: TMDV | B5: TMDV | C5: ProShares Russell US Dividend Growers ETF | D5: {=_FV(A5,"Last trade time",TRUE)} -> #VALUE! | E5: {=_FV(A5,"Price")} -> #VALUE! | F5: {=_FV(A5,"Change (%)",TRUE)} -> #VALUE! | G5: {=_FV(A5,"Change")} -> #VALUE! | H5: {=_FV(A5,"Open")} -> #VALUE! | I5: {=_FV(A5,"Low")} -> #VALUE! | J5: {=_FV(A5,"High")} -> #VALUE! | K5: {=_FV(A5,"Previous close",TRUE)} -> #VALUE! | M5: {=_FV(A5,"52 week low",TRUE)} -> #VALUE! | N5: {=_FV(A5,"52 week high",TRUE)} -> #VALUE! | O5: {=_FV(A5,"Volume")} -> #VALUE! | P5: {=_FV(A5,"Volume average",TRUE)} -> #VALUE! | Q5: Mid-Cap Value | S5: ProShares | T5: {=_FV(A5,"Expense ratio",TRUE)} -> #VALUE! | U5: {=_FV(A5,"Market cap",TRUE)} -> #VALUE! | V5: 4248592 | W5: 4248592 | Y5: 2019-11-04 | Z5: 46.9521 | AA5: 20.130634 | AB5: 0.027999999 | AC5: 233 | AE5: 1.8690309 | AF5: 4.9194103 | AI5: 233 | AJ5: 10938.581 | AL5: 51.754 | AM5: 42.69 | AN5: Low | AO5: {=_FV(A5,"Currency")} -> #VALUE! | AP5: {=_FV(A5,"Exchange")} -> #VALUE! | AQ5: {=_FV(A5,"Exchange abbreviation",TRUE)} -> #VALUE! | AR5: {=_FV(A5,"Instrument type",TRUE)} -> #VALUE!
A6: #VALUE! | B6: CARD | C6: Bank Of Montreal MAX Auto Industry -3x Inverse Leveraged ETN | D6: {=_FV(A6,"Last trade time",TRUE)} -> 45824.84 | E6: {=_FV(A6,"Price")} -> 4.4 | F6: {=_FV(A6,"Change (%)",TRUE)} -> -0.022222 | G6: {=_FV(A6,"Change")} -> -0.1 | H6: {=_FV(A6,"Open")} -> 4.4099 | I6: {=_FV(A6,"Low")} -> 4.3392 | J6: {=_FV(A6,"High")} -> 4.4399 | K6: {=_FV(A6,"Previous close",TRUE)} -> 4.5 | M6: {=_FV(A6,"52 week low",TRUE)} -> 3.845 | N6: {=_FV(A6,"52 week high",TRUE)} -> 15.35 | O6: {=_FV(A6,"Volume")} -> 5763 | P6: {=_FV(A6,"Volume average",TRUE)} -> 16572 | Q6: Trading--Inverse Equity | R6: Equities - Autos - Short | S6: Bank of Montreal | T6: {=_FV(A6,"Expense ratio",TRUE)} -> #VALUE! | U6: {=_FV(A6,"Market cap",TRUE)} -> 104909700000 | V6: 1240271 | W6: 1240271 | X6: -71.20% | Y6: 2023-06-26 | Z6: 4.31998 | AA6: 15.021212 | AB6: 0 | AC6: 32947 | AE6: -41.222659 | AI6: 32947 | AJ6: 142327.75 | AL6: 13.6 | AM6: 3.845 | AN6: Low | AO6: {=_FV(A6,"Currency")} -> USD | AP6: {=_FV(A6,"Exchange")} -> NYSE Arca | AQ6: {=_FV(A6,"Exchange abbreviation",TRUE)} -> ARCX | AR6: {=_FV(A6,"Instrument type",TRUE)} -> Stock
A7: #VALUE! | B7: FLYD | C7: Bank of Montreal MicroSectors Travel -3x Inverse Leveraged ETN | D7: {=_FV(A7,"Last trade time",TRUE)} -> 45824.84 | E7: {=_FV(A7,"Price")} -> 10.37 | F7: {=_FV(A7,"Change (%)",TRUE)} -> -0.079041 | G7: {=_FV(A7,"Change")} -> -0.89 | H7: {=_FV(A7,"Open")} -> 10.695 | I7: {=_FV(A7,"Low")} -> 10.335 | J7: {=_FV(A7,"High")} -> 10.73 | K7: {=_FV(A7,"Previous close",TRUE)} -> 11.26 | M7: {=_FV(A7,"52 week low",TRUE)} -> 9.59 | N7: {=_FV(A7,"52 week high",TRUE)} -> 42.88 | O7: {=_FV(A7,"Volume")} -> 10616 | P7: {=_FV(A7,"Volume average",TRUE)} -> 9870 | Q7: Financial | T7: {=_FV(A7,"Expense ratio",TRUE)} -> #VALUE! | U7: {=_FV(A7,"Market cap",TRUE)} -> 104909700000 | AC7: 7131 | AN7: Unknown | AO7: {=_FV(A7,"Currency")} -> USD | AP7: {=_FV(A7,"Exchange")} -> NYSE Arca | AQ7: {=_FV(A7,"Exchange abbreviation",TRUE)} -> ARCX | AR7: {=_FV(A7,"Instrument type",TRUE)} -> Stock
A8: #VALUE! | B8: NRGU | C8: Bank Of Montreal MicroSectors U.S. Big Oil 3 Leveraged ETNs du | D8: {=_FV(A8,"Last trade time",TRUE)} -> 45824.918 | E8: {=_FV(A8,"Price")} -> 18.51 | F8: {=_FV(A8,"Change (%)",TRUE)} -> -0.010689 | G8: {=_FV(A8,"Change")} -> -0.2 | H8: {=_FV(A8,"Open")} -> 18.71 | I8: {=_FV(A8,"Low")} -> 17.97 | J8: {=_FV(A8,"High")} -> 19 | K8: {=_FV(A8,"Previous close",TRUE)} -> 18.71 | M8: {=_FV(A8,"52 week low",TRUE)} -> 10.2801 | N8: {=_FV(A8,"52 week high",TRUE)} -> 26.1206 | O8: {=_FV(A8,"Volume")} -> 174302 | P8: {=_FV(A8,"Volume average",TRUE)} -> 46231 | Q8: Financial | T8: {=_FV(A8,"Expense ratio",TRUE)} -> #VALUE! | U8: {=_FV(A8,"Market cap",TRUE)} -> 104909700000 | Z8: 15.6417 | AA8: 9.666164 | AC8: 32011 | AE8: -40.117147 | AI8: 32011 | AJ8: 490728.63 | AL8: 26.121 | AM8: 10.28 | AN8: Low | AO8: {=_FV(A8,"Currency")} -> USD | AP8: {=_FV(A8,"Exchange")} -> NYSE Arca | AQ8: {=_FV(A8,"Exchange abbreviation",TRUE)} -> ARCX | AR8: {=_FV(A8,"Instrument type",TRUE)} -> Stock
A9: #VALUE! | B9: GDXU | C9: MicroSectors Gold Miners 3X Leveraged ETN | D9: {=_FV(A9,"Last trade time",TRUE)} -> 45824.941 | E9: {=_FV(A9,"Price")} -> 80.93 | F9: {=_FV(A9,"Change (%)",TRUE)} -> -0.05665 | G9: {=_FV(A9,"Change")} -> -4.86 | H9: {=_FV(A9,"Open")} -> 82.39 | I9: {=_FV(A9,"Low")} -> 80.5 | J9: {=_FV(A9,"High")} -> 84.1605 | K9: {=_FV(A9,"Previous close",TRUE)} -> 85.79 | M9: {=_FV(A9,"52 week low",TRUE)} -> 25.83 | N9: {=_FV(A9,"52 week high",TRUE)} -> 87.5 | O9: {=_FV(A9,"Volume")} -> 485805 | P9: {=_FV(A9,"Volume average",TRUE)} -> 824987 | Q9: Trading--Leveraged Commodities | R9: Commodities - Gold | S9: BMO Capital Markets | T9: {=_FV(A9,"Expense ratio",TRUE)} -> #VALUE! | U9: {=_FV(A9,"Market cap",TRUE)} -> 104909700000 | V9: 593497472 | W9: 593497472 | Y9: 2020-12-01 | Z9: 74.89052 | AA9: 23.022688 | AB9: 0 | AC9: 809814 | AE9: 150.81593 | AF9: 83.632022 | AI9: 809814 | AJ9: 60574087 | AL9: 87.5 | AM9: 25.83 | AN9: High | AO9: {=_FV(A9,"Currency")} -> USD | AP9: {=_FV(A9,"Exchange")} -> NYSE Arca | AQ9: {=_FV(A9,"Exchange abbreviation",TRUE)} -> ARCX | AR9: {=_FV(A9,"Instrument type",TRUE)} -> Stock
A10: #VALUE! | B10: WTIU | C10: Bank Of Montreal MicroSectors Energy 3X Leveraged ETNs | D10: {=_FV(A10,"Last trade time",TRUE)} -> 45824.92 | E10: {=_FV(A10,"Price")} -> 10.48 | F10: {=_FV(A10,"Change (%)",TRUE)} -> -0.003802 | G10: {=_FV(A10,"Change")} -> -0.04 | H10: {=_FV(A10,"Open")} -> 10.5 | I10: {=_FV(A10,"Low")} -> 10.19 | J10: {=_FV(A10,"High")} -> 10.78 | K10: {=_FV(A10,"Previous close",TRUE)} -> 10.52 | M10: {=_FV(A10,"52 week low",TRUE)} -> 6.056 | N10: {=_FV(A10,"52 week high",TRUE)} -> 20.33 | O10: {=_FV(A10,"Volume")} -> 192442 | P10: {=_FV(A10,"Volume average",TRUE)} -> 79504 | Q10: Trading--Leveraged Equity | S10: BMO Capital Markets | T10: {=_FV(A10,"Expense ratio",TRUE)} -> #VALUE! | U10: {=_FV(A10,"Market cap",TRUE)} -> 104909700000 | V10: 12352514 | W10: 12352514 | Y10: 2023-02-15 | Z10: 8.77648 | AA10: 15.339239 | AB10: 0 | AC10: 69295 | AE10: -24.72388 | AF10: -52.224321 | AI10: 69295 | AJ10: 609103.05 | AL10: 20.33 | AM10: 6.056 | AN10: Low | AO10: {=_FV(A10,"Currency")} -> USD | AP10: {=_FV(A10,"Exchange")} -> NYSE Arca | AQ10: {=_FV(A10,"Exchange abbreviation",TRUE)} -> ARCX | AR10: {=_FV(A10,"Instrument type",TRUE)} -> Stock
A11: #VALUE! | B11: OILU | C11: MicroSectors Oil & Gas Exp. & Prod. 3x Leveraged ETN | D11: {=_FV(A11,"Last trade time",TRUE)} -> 45824.94 | E11: {=_FV(A11,"Price")} -> 24.15 | F11: {=_FV(A11,"Change (%)",TRUE)} -> -0.014688 | G11: {=_FV(A11,"Change")} -> -0.36 | H11: {=_FV(A11,"Open")} -> 24.3 | I11: {=_FV(A11,"Low")} -> 23.66 | J11: {=_FV(A11,"High")} -> 25 | K11: {=_FV(A11,"Previous close",TRUE)} -> 24.51 | M11: {=_FV(A11,"52 week low",TRUE)} -> 15.15 | N11: {=_FV(A11,"52 week high",TRUE)} -> 43.77 | O11: {=_FV(A11,"Volume")} -> 618210 | P11: {=_FV(A11,"Volume average",TRUE)} -> 255748 | Q11: Trading--Leveraged Equity | S11: BMO Capital Markets | T11: {=_FV(A11,"Expense ratio",TRUE)} -> #VALUE! | U11: {=_FV(A11,"Market cap",TRUE)} -> 104909700000 | V11: 29153108 | W11: 29153108 | Y11: 2021-11-07 | Z11: 20.85666 | AA11: 15.421977 | AB11: 0 | AC11: 229084 | AE11: -26.781207 | AF11: -46.552342 | AI11: 229084 | AJ11: 4764947.2 | AL11: 43.77 | AM11: 15.15 | AN11: Medium | AO11: {=_FV(A11,"Currency")} -> USD | AP11: {=_FV(A11,"Exchange")} -> NYSE Arca | AQ11: {=_FV(A11,"Exchange abbreviation",TRUE)} -> ARCX | AR11: {=_FV(A11,"Instrument type",TRUE)} -> Stock
A12: #VALUE! | B12: JETD | C12: Bank Of Montreal MAX Airlines -3X Inverse Leveraged ETNs | D12: {=_FV(A12,"Last trade time",TRUE)} -> 45824.84 | E12: {=_FV(A12,"Price")} -> 9.7482 | F12: {=_FV(A12,"Change (%)",TRUE)} -> -0.056682 | G12: {=_FV(A12,"Change")} -> -0.5857 | H12: {=_FV(A12,"Open")} -> 9.91 | I12: {=_FV(A12,"Low")} -> 9.62 | J12: {=_FV(A12,"High")} -> 9.919 | K12: {=_FV(A12,"Previous close",TRUE)} -> 10.3339 | M12: {=_FV(A12,"52 week low",TRUE)} -> 8.78 | N12: {=_FV(A12,"52 week high",TRUE)} -> 27.74 | O12: {=_FV(A12,"Volume")} -> 11594 | P12: {=_FV(A12,"Volume average",TRUE)} -> 15050 | Q12: Trading--Inverse Equity | R12: Equities - Airlines - Short | S12: Bank of Montreal | T12: {=_FV(A12,"Expense ratio",TRUE)} -> #VALUE! | U12: {=_FV(A12,"Market cap",TRUE)} -> 104909700000 | V12: 1932554 | W12: 1932554 | Y12: 2023-06-19 | Z12: 8.98953 | AA12: 14.365964 | AB12: 0 | AC12: 15596 | AE12: -28.907496 | AF12: -58.023356 | AI12: 15596 | AJ12: 140675.92 | AL12: 27.74 | AM12: 8.78 | AN12: Low | AO12: {=_FV(A12,"Currency")} -> USD | AP12: {=_FV(A12,"Exchange")} -> NYSE Arca | AQ12: {=_FV(A12,"Exchange abbreviation",TRUE)} -> ARCX | AR12: {=_FV(A12,"Instrument type",TRUE)} -> Stock
A13: #VALUE! | B13: VXX | C13: Barclays PLC | D13: {=_FV(A13,"Last trade time",TRUE)} -> 45824.941 | E13: {=_FV(A13,"Price")} -> 51.37 | F13: {=_FV(A13,"Change (%)",TRUE)} -> -0.06854 | G13: {=_FV(A13,"Change")} -> -3.78 | H13: {=_FV(A13,"Open")} -> 52.97 | I13: {=_FV(A13,"Low")} -> 50.84 | J13: {=_FV(A13,"High")} -> 52.98 | K13: {=_FV(A13,"Previous close",TRUE)} -> 55.15 | M13: {=_FV(A13,"52 week low",TRUE)} -> 39.98 | N13: {=_FV(A13,"52 week high",TRUE)} -> 91.19 | O13: {=_FV(A13,"Volume")} -> 6923148 | P13: {=_FV(A13,"Volume average",TRUE)} -> 4636047 | Q13: Trading--Miscellaneous | S13: iPath | T13: {=_FV(A13,"Expense ratio",TRUE)} -> #VALUE! | U13: {=_FV(A13,"Market cap",TRUE)} -> #VALUE! | V13: 389340224 | W13: 389340224 | Y13: 2018-01-16 | Z13: 50.7358 | AB13: 0 | AC13: 6998523 | AE13: 7.4295464 | AF13: 11.822222 | AI13: 6998523 | AJ13: 3.5559495e+08 | AL13: 91.19 | AM13: 39.98 | AN13: High | AO13: {=_FV(A13,"Currency")} -> USD | AP13: {=_FV(A13,"Exchange")} -> CBOE BZX Exchange | AQ13: {=_FV(A13,"Exchange abbreviation",TRUE)} -> BATS | AR13: {=_FV(A13,"Instrument type",TRUE)} -> Stock
A14: #VALUE! | B14: SHNY | C14: Bank Of Montreal MicroSectors Gold 3X Leveraged ETNs due Janua | D14: {=_FV(A14,"Last trade time",TRUE)} -> 45824.916 | E14: {=_FV(A14,"Price")} -> 76.28 | F14: {=_FV(A14,"Change (%)",TRUE)} -> -0.041829 | G14: {=_FV(A14,"Change")} -> -3.33 | H14: {=_FV(A14,"Open")} -> 78.45 | I14: {=_FV(A14,"Low")} -> 76.08 | J14: {=_FV(A14,"High")} -> 78.45 | K14: {=_FV(A14,"Previous close",TRUE)} -> 79.61 | M14: {=_FV(A14,"52 week low",TRUE)} -> 32.68 | N14: {=_FV(A14,"52 week high",TRUE)} -> 86.5625 | O14: {=_FV(A14,"Volume")} -> 107325 | P14: {=_FV(A14,"Volume average",TRUE)} -> 123633 | Q14: Trading--Leveraged Commodities | R14: Commodities - Gold | S14: BMO Capital Markets | T14: {=_FV(A14,"Expense ratio",TRUE)} -> #VALUE! | U14: {=_FV(A14,"Market cap",TRUE)} -> 104909700000 | V14: 71322512 | W14: 71322512 | Y14: 2023-02-20 | Z14: 71.93627 | AB14: 0 | AC14: 113239 | AE14: 68.71379 | AF14: 97.890634 | AI14: 113239 | AJ14: 8143016.5 | AL14: 86.563 | AM14: 32.68 | AN14: Medium | AO14: {=_FV(A14,"Currency")} -> USD | AP14: {=_FV(A14,"Exchange")} -> NYSE Arca | AQ14: {=_FV(A14,"Exchange abbreviation",TRUE)} -> ARCX | AR14: {=_FV(A14,"Instrument type",TRUE)} -> Stock
A15: #VALUE! | B15: DGP | C15: DB Gold Double Long ETN Exp 15 Feb 2038 | D15: {=_FV(A15,"Last trade time",TRUE)} -> 45824.849 | E15: {=_FV(A15,"Price")} -> 105.01 | F15: {=_FV(A15,"Change (%)",TRUE)} -> -0.021342 | G15: {=_FV(A15,"Change")} -> -2.29 | H15: {=_FV(A15,"Open")} -> 106.8 | I15: {=_FV(A15,"Low")} -> 104.95 | J15: {=_FV(A15,"High")} -> 106.83 | K15: {=_FV(A15,"Previous close",TRUE)} -> 107.3 | M15: {=_FV(A15,"52 week low",TRUE)} -> 52.2301 | N15: {=_FV(A15,"52 week high",TRUE)} -> 109.72 | O15: {=_FV(A15,"Volume")} -> 46206 | P15: {=_FV(A15,"Volume average",TRUE)} -> 23389 | Q15: Trading--Leveraged Commodities | R15: Commodities - Gold | S15: Deutsche Bank AG | T15: {=_FV(A15,"Expense ratio",TRUE)} -> #VALUE! | U15: {=_FV(A15,"Market cap",TRUE)} -> #VALUE! | V15: 163395040 | W15: 163395040 | Y15: 2008-02-26 | Z15: 101.34806 | AB15: 0 | AC15: 29142 | AE15: 48.8515 | AF15: 81.516502 | AI15: 29142 | AJ15: 2922942.6 | AL15: 109.72 | AM15: 52.23 | AN15: Medium | AO15: {=_FV(A15,"Currency")} -> USD | AP15: {=_FV(A15,"Exchange")} -> NYSE Arca | AQ15: {=_FV(A15,"Exchange abbreviation",TRUE)} -> ARCX | AR15: {=_FV(A15,"Instrument type",TRUE)} -> Stock
A16: #VALUE! | B16: BERZ | C16: MicroSectors FANG & Innovation -3x Inverse Leveraged ETN | D16: {=_FV(A16,"Last trade time",TRUE)} -> 45824.878 | E16: {=_FV(A16,"Price")} -> 6.51 | F16: {=_FV(A16,"Change (%)",TRUE)} -> -0.073969 | G16: {=_FV(A16,"Change")} -> -0.52 | H16: {=_FV(A16,"Open")} -> 6.81 | I16: {=_FV(A16,"Low")} -> 6.48 | J16: {=_FV(A16,"High")} -> 6.81 | K16: {=_FV(A16,"Previous close",TRUE)} -> 7.03 | M16: {=_FV(A16,"52 week low",TRUE)} -> 6.48 | N16: {=_FV(A16,"52 week high",TRUE)} -> 31.62 | O16: {=_FV(A16,"Volume")} -> 511193 | P16: {=_FV(A16,"Volume average",TRUE)} -> 301662 | Q16: Trading--Inverse Equity | R16: Equities - - Short | S16: BMO Capital Markets | T16: {=_FV(A16,"Expense ratio",TRUE)} -> #VALUE! | U16: {=_FV(A16,"Market cap",TRUE)} -> 104909700000 | V16: 5334667 | W16: 5334667 | X16: -70.34% | Y16: 2021-08-16 | Z16: 7.1063 | AA16: 31.97148 | AB16: 0 | AC16: 274288 | AE16: -48.624536 | AF16: -71.136175 | AI16: 274288 | AJ16: 1947444.8 | AL16: 31.62 | AM16: 6.86 | AN16: Medium | AO16: {=_FV(A16,"Currency")} -> USD | AP16: {=_FV(A16,"Exchange")} -> NYSE Arca | AQ16: {=_FV(A16,"Exchange abbreviation",TRUE)} -> ARCX | AR16: {=_FV(A16,"Instrument type",TRUE)} -> Stock
A17: #VALUE! | B17: DJP | C17: Barclays Bank iPath Bloomberg Commodity Index Total Return ETN Exp 12 June | D17: {=_FV(A17,"Last trade time",TRUE)} -> 45824.84 | E17: {=_FV(A17,"Price")} -> 35.27 | F17: {=_FV(A17,"Change (%)",TRUE)} -> 0.003414 | G17: {=_FV(A17,"Change")} -> 0.12 | H17: {=_FV(A17,"Open")} -> 35.28 | I17: {=_FV(A17,"Low")} -> 35.01 | J17: {=_FV(A17,"High")} -> 35.3646 | K17: {=_FV(A17,"Previous close",TRUE)} -> 35.15 | M17: {=_FV(A17,"52 week low",TRUE)} -> 29.3501 | N17: {=_FV(A17,"52 week high",TRUE)} -> 35.78 | O17: {=_FV(A17,"Volume")} -> 316915 | P17: {=_FV(A17,"Volume average",TRUE)} -> 37367 | Q17: Commodities Broad Basket | R17: Commodities - Diversified | S17: iPath | T17: {=_FV(A17,"Expense ratio",TRUE)} -> #VALUE! | U17: {=_FV(A17,"Market cap",TRUE)} -> #VALUE! | V17: 558780352 | W17: 558780352 | Y17: 2006-06-05 | Z17: 34.3786 | AB17: 0 | AC17: 60212 | AE17: 6.0839943 | AF17: 4.2805097 | AI17: 60212 | AJ17: 2068884.3 | AL17: 35.78 | AM17: 29.35 | AN17: Medium | AO17: {=_FV(A17,"Currency")} -> USD | AP17: {=_FV(A17,"Exchange")} -> NYSE Arca | AQ17: {=_FV(A17,"Exchange abbreviation",TRUE)} -> ARCX | AR17: {=_FV(A17,"Instrument type",TRUE)} -> Stock
A18: #VALUE! | B18: FNGD | C18: NO Name | D18: {=_FV(A18,"Last trade time",TRUE)} -> 45824.932 | E18: {=_FV(A18,"Price")} -> 7.4893 | F18: {=_FV(A18,"Change (%)",TRUE)} -> -0.038601 | G18: {=_FV(A18,"Change")} -> -0.3007 | H18: {=_FV(A18,"Open")} -> 7.66 | I18: {=_FV(A18,"Low")} -> 7.4 | J18: {=_FV(A18,"High")} -> 7.66 | K18: {=_FV(A18,"Previous close",TRUE)} -> 7.79 | M18: {=_FV(A18,"52 week low",TRUE)} -> 7.4 | N18: {=_FV(A18,"52 week high",TRUE)} -> 36.67 | O18: {=_FV(A18,"Volume")} -> 4431949 | P18: {=_FV(A18,"Volume average",TRUE)} -> 4344211 | Q18: Other | T18: {=_FV(A18,"Expense ratio",TRUE)} -> #VALUE! | U18: {=_FV(A18,"Market cap",TRUE)} -> 104909700000 | AC18: 4425987 | AN18: Unknown | AO18: {=_FV(A18,"Currency")} -> USD | AP18: {=_FV(A18,"Exchange")} -> NYSE Arca | AQ18: {=_FV(A18,"Exchange abbreviation",TRUE)} -> ARCX | AR18: {=_FV(A18,"Instrument type",TRUE)} -> Stock
A19: #VALUE! | B19: USML | C19: ETRACS 2x Leveraged MSCI US Minimum Volatility Factor TR ETN | D19: {=_FV(A19,"Last trade time",TRUE)} -> 45824.84 | E19: {=_FV(A19,"Price")} -> 41.2629 | F19: {=_FV(A19,"Change (%)",TRUE)} -> 0.001908 | G19: {=_FV(A19,"Change")} -> 0.0786 | H19: {=_FV(A19,"Open")} -> 41.2629 | I19: {=_FV(A19,"Low")} -> 41.2629 | J19: {=_FV(A19,"High")} -> 41.2629 | K19: {=_FV(A19,"Previous close",TRUE)} -> 41.1843 | M19: {=_FV(A19,"52 week low",TRUE)} -> 34.2953 | N19: {=_FV(A19,"52 week high",TRUE)} -> 47.66 | O19: {=_FV(A19,"Volume")} -> 0 | P19: {=_FV(A19,"Volume average",TRUE)} -> 253 | Q19: Trading--Leveraged Equity | S19: UBS | T19: {=_FV(A19,"Expense ratio",TRUE)} -> #VALUE! | U19: {=_FV(A19,"Market cap",TRUE)} -> 76546930000 | V19: 12542970 | W19: 12542970 | Y19: 2021-02-04 | Z19: 41.9514 | AB19: 0 | AC19: 214 | AE19: 8.6122114 | AF19: 20.705484 | AI19: 214 | AJ19: 8993.3928 | AL19: 47.66 | AM19: 34.278 | AN19: Low | AO19: {=_FV(A19,"Currency")} -> USD | AP19: {=_FV(A19,"Exchange")} -> NYSE Arca | AQ19: {=_FV(A19,"Exchange abbreviation",TRUE)} -> ARCX | AR19: {=_FV(A19,"Instrument type",TRUE)} -> Stock
A20: #VALUE! | B20: VXZ | C20: Barclays PLC | D20: {=_FV(A20,"Last trade time",TRUE)} -> 45824.84 | E20: {=_FV(A20,"Price")} -> 59.38 | F20: {=_FV(A20,"Change (%)",TRUE)} -> -0.026876 | G20: {=_FV(A20,"Change")} -> -1.64 | H20: {=_FV(A20,"Open")} -> 59.55 | I20: {=_FV(A20,"Low")} -> 58.84 | J20: {=_FV(A20,"High")} -> 59.55 | K20: {=_FV(A20,"Previous close",TRUE)} -> 61.02 | M20: {=_FV(A20,"52 week low",TRUE)} -> 47.5 | N20: {=_FV(A20,"52 week high",TRUE)} -> 69.33 | O20: {=_FV(A20,"Volume")} -> 6140 | P20: {=_FV(A20,"Volume average",TRUE)} -> 11620 | Q20: Trading--Miscellaneous | S20: iPath | T20: {=_FV(A20,"Expense ratio",TRUE)} -> #VALUE! | U20: {=_FV(A20,"Market cap",TRUE)} -> #VALUE! | V20: 36265044 | W20: 36265044 | Y20: 2018-01-16 | Z20: 58.8354 | AB20: 0 | AC20: 31736 | AE20: 15.566034 | AF20: 20.196242 | AI20: 31736 | AJ20: 1868615.7 | AL20: 69.33 | AM20: 47.5 | AN20: Medium | AO20: {=_FV(A20,"Currency")} -> USD | AP20: {=_FV(A20,"Exchange")} -> CBOE BZX Exchange | AQ20: {=_FV(A20,"Exchange abbreviation",TRUE)} -> BATS | AR20: {=_FV(A20,"Instrument type",TRUE)} -> Stock
A21: #VALUE! | B21: SCDL | C21: ETRACS 2x Leveraged US Dividend Factor TR ETN | D21: {=_FV(A21,"Last trade time",TRUE)} -> 45824.84 | E21: {=_FV(A21,"Price")} -> 37.1143 | F21: {=_FV(A21,"Change (%)",TRUE)} -> 0.001863 | G21: {=_FV(A21,"Change")} -> 0.069 | H21: {=_FV(A21,"Open")} -> 37.1143 | I21: {=_FV(A21,"Low")} -> 37.1143 | J21: {=_FV(A21,"High")} -> 37.1143 | K21: {=_FV(A21,"Previous close",TRUE)} -> 37.0453 | M21: {=_FV(A21,"52 week low",TRUE)} -> 29.83 | N21: {=_FV(A21,"52 week high",TRUE)} -> 44.8993 | O21: {=_FV(A21,"Volume")} -> 22 | P21: {=_FV(A21,"Volume average",TRUE)} -> 3 | Q21: Trading--Leveraged Equity | S21: UBS | T21: {=_FV(A21,"Expense ratio",TRUE)} -> #VALUE! | U21: {=_FV(A21,"Market cap",TRUE)} -> 76546930000 | V21: 10595610 | W21: 10595610 | Y21: 2021-02-04 | Z21: 36.2171 | AB21: 0 | AC21: 711 | AE21: -5.6190533 | AF21: 4.5696804 | AI21: 711 | AJ21: 25763.369 | AL21: 44.899 | AM21: 29.83 | AN21: Low | AO21: {=_FV(A21,"Currency")} -> USD | AP21: {=_FV(A21,"Exchange")} -> NYSE Arca | AQ21: {=_FV(A21,"Exchange abbreviation",TRUE)} -> ARCX | AR21: {=_FV(A21,"Instrument type",TRUE)} -> Stock
A22: #VALUE! | B22: USOI | C22: Ubs Ag Etracs Crude Oil Shares Covered Call ETN Exp 24th Apr 2037 | D22: {=_FV(A22,"Last trade time",TRUE)} -> 45824.929 | E22: {=_FV(A22,"Price")} -> 56.22 | F22: {=_FV(A22,"Change (%)",TRUE)} -> -0.005484 | G22: {=_FV(A22,"Change")} -> -0.31 | H22: {=_FV(A22,"Open")} -> 56.89 | I22: {=_FV(A22,"Low")} -> 55.77 | J22: {=_FV(A22,"High")} -> 56.9455 | K22: {=_FV(A22,"Previous close",TRUE)} -> 56.53 | M22: {=_FV(A22,"52 week low",TRUE)} -> 50.05 | N22: {=_FV(A22,"52 week high",TRUE)} -> 75.9903 | O22: {=_FV(A22,"Volume")} -> 142590 | P22: {=_FV(A22,"Volume average",TRUE)} -> 70145 | Q22: Commodities Focused | R22: Commodities - Oil | S22: UBS AG | T22: {=_FV(A22,"Expense ratio",TRUE)} -> #VALUE! | U22: {=_FV(A22,"Market cap",TRUE)} -> 76546930000 | V22: 290861312 | W22: 290861312 | Y22: 2017-04-24 | Z22: 55.6482 | AB22: 0.24120001 | AC22: 48207 | AE22: -7.6515029 | AF22: -2.0416446 | AI22: 48207 | AJ22: 2700556.1 | AL22: 75.99 | AM22: 50.05 | AN22: Medium | AO22: {=_FV(A22,"Currency")} -> USD | AP22: {=_FV(A22,"Exchange")} -> Nasdaq Stock Market | AQ22: {=_FV(A22,"Exchange abbreviation",TRUE)} -> XNAS | AR22: {=_FV(A22,"Instrument type",TRUE)} -> Stock
A23: #VALUE! | B23: BNKD | C23: Bank Of Montreal MicroSectors U.S. Big Banks -3 Inverse Leve | D23: {=_FV(A23,"Last trade time",TRUE)} -> 45824.84 | E23: {=_FV(A23,"Price")} -> 23.2586 | F23: {=_FV(A23,"Change (%)",TRUE)} -> -0.047161 | G23: {=_FV(A23,"Change")} -> -1.1512 | H23: {=_FV(A23,"Open")} -> 23.2586 | I23: {=_FV(A23,"Low")} -> 23.2586 | J23: {=_FV(A23,"High")} -> 23.2586 | K23: {=_FV(A23,"Previous close",TRUE)} -> 24.4098 | M23: {=_FV(A23,"52 week low",TRUE)} -> 22.46 | N23: {=_FV(A23,"52 week high",TRUE)} -> 56.76 | O23: {=_FV(A23,"Volume")} -> 88 | P23: {=_FV(A23,"Volume average",TRUE)} -> 445 | Q23: Financial | T23: {=_FV(A23,"Expense ratio",TRUE)} -> #VALUE! | U23: {=_FV(A23,"Market cap",TRUE)} -> 104909700000 | X23: -15.14% | AC23: 455 | AN23: Unknown | AO23: {=_FV(A23,"Currency")} -> USD | AP23: {=_FV(A23,"Exchange")} -> NYSE Arca | AQ23: {=_FV(A23,"Exchange abbreviation",TRUE)} -> ARCX | AR23: {=_FV(A23,"Instrument type",TRUE)} -> Stock
A24: #VALUE! | B24: GLDI | C24: Ubs Ag Etracs Gold Shares Covered Call ETN Exp 02 Feb 2033 | D24: {=_FV(A24,"Last trade time",TRUE)} -> 45824.867 | E24: {=_FV(A24,"Price")} -> 163.56 | F24: {=_FV(A24,"Change (%)",TRUE)} -> -0.007524 | G24: {=_FV(A24,"Change")} -> -1.24 | H24: {=_FV(A24,"Open")} -> 164.51 | I24: {=_FV(A24,"Low")} -> 163.11 | J24: {=_FV(A24,"High")} -> 164.8923 | K24: {=_FV(A24,"Previous close",TRUE)} -> 164.8 | M24: {=_FV(A24,"52 week low",TRUE)} -> 141.74 | N24: {=_FV(A24,"52 week high",TRUE)} -> 166.79 | O24: {=_FV(A24,"Volume")} -> 6574 | P24: {=_FV(A24,"Volume average",TRUE)} -> 8851 | Q24: Commodities Focused | R24: Commodities - Gold | S24: UBS AG | T24: {=_FV(A24,"Expense ratio",TRUE)} -> #VALUE! | U24: {=_FV(A24,"Market cap",TRUE)} -> 76546930000 | V24: 111699984 | W24: 111699984 | Y24: 2013-01-28 | Z24: 162.1176 | AB24: 0.14050001 | AC24: 8811 | AE24: 11.995684 | AF24: 23.632736 | AI24: 8811 | AJ24: 1423240.8 | AL24: 166.79 | AM24: 141.74 | AN24: Medium | AO24: {=_FV(A24,"Currency")} -> USD | AP24: {=_FV(A24,"Exchange")} -> Nasdaq Stock Market | AQ24: {=_FV(A24,"Exchange abbreviation",TRUE)} -> XNAS | AR24: {=_FV(A24,"Instrument type",TRUE)} -> Stock
A25: #VALUE! | B25: ATMP | C25: Barclays PLC | D25: {=_FV(A25,"Last trade time",TRUE)} -> 45824.84 | E25: {=_FV(A25,"Price")} -> 29.02 | F25: {=_FV(A25,"Change (%)",TRUE)} -> -0.012253 | G25: {=_FV(A25,"Change")} -> -0.36 | H25: {=_FV(A25,"Open")} -> 29.19 | I25: {=_FV(A25,"Low")} -> 28.95 | J25: {=_FV(A25,"High")} -> 29.261 | K25: {=_FV(A25,"Previous close",TRUE)} -> 29.38 | M25: {=_FV(A25,"52 week low",TRUE)} -> 24.02 | N25: {=_FV(A25,"52 week high",TRUE)} -> 32.09 | O25: {=_FV(A25,"Volume")} -> 14815 | P25: {=_FV(A25,"Volume average",TRUE)} -> 21132 | Q25: Other | T25: {=_FV(A25,"Expense ratio",TRUE)} -> #VALUE! | U25: {=_FV(A25,"Market cap",TRUE)} -> 45350550000 | X25: 20.04% | AC25: 21313 | AN25: Unknown | AO25: {=_FV(A25,"Currency")} -> USD | AP25: {=_FV(A25,"Exchange")} -> CBOE BZX Exchange | AQ25: {=_FV(A25,"Exchange abbreviation",TRUE)} -> BATS | AR25: {=_FV(A25,"Instrument type",TRUE)} -> Stock
A26: #VALUE! | B26: IWFL | C26: ETRACS 2x Leveraged US Growth Factor TR ETN | D26: {=_FV(A26,"Last trade time",TRUE)} -> 45824.84 | E26: {=_FV(A26,"Price")} -> 44.8862 | F26: {=_FV(A26,"Change (%)",TRUE)} -> 0.022113 | G26: {=_FV(A26,"Change")} -> 0.9711 | H26: {=_FV(A26,"Open")} -> 44.8862 | I26: {=_FV(A26,"Low")} -> 44.8862 | J26: {=_FV(A26,"High")} -> 44.8862 | K26: {=_FV(A26,"Previous close",TRUE)} -> 43.9151 | M26: {=_FV(A26,"52 week low",TRUE)} -> 26.45 | N26: {=_FV(A26,"52 week high",TRUE)} -> 53.85 | O26: {=_FV(A26,"Volume")} -> 64 | P26: {=_FV(A26,"Volume average",TRUE)} -> 413 | Q26: Size/Style | R26: Equities - Growth Factor | T26: {=_FV(A26,"Expense ratio",TRUE)} -> #VALUE! | U26: {=_FV(A26,"Market cap",TRUE)} -> 76546930000 | AC26: 366 | AN26: Unknown | AO26: {=_FV(A26,"Currency")} -> USD | AP26: {=_FV(A26,"Exchange")} -> NYSE Arca | AQ26: {=_FV(A26,"Exchange abbreviation",TRUE)} -> ARCX | AR26: {=_FV(A26,"Instrument type",TRUE)} -> Stock
A27: #VALUE! | B27: TXUG | C27: Thornburg International Growth Fund ETF | D27: {=_FV(A27,"Last trade time",TRUE)} -> 45824.844 | E27: {=_FV(A27,"Price")} -> 25.6725 | F27: {=_FV(A27,"Change (%)",TRUE)} -> 0.004166 | G27: {=_FV(A27,"Change")} -> 0.1065 | H27: {=_FV(A27,"Open")} -> 25.6725 | I27: {=_FV(A27,"Low")} -> 25.6725 | J27: {=_FV(A27,"High")} -> 25.6725 | K27: {=_FV(A27,"Previous close",TRUE)} -> 25.566 | M27: {=_FV(A27,"52 week low",TRUE)} -> 21.26 | N27: {=_FV(A27,"52 week high",TRUE)} -> 26.1405 | O27: {=_FV(A27,"Volume")} -> 68 | P27: {=_FV(A27,"Volume average",TRUE)} -> 313 | Q27: Foreign Large Growth | S27: Thornburg | T27: {=_FV(A27,"Expense ratio",TRUE)} -> #VALUE! | U27: {=_FV(A27,"Market cap",TRUE)} -> #VALUE! | V27: 5082172 | W27: 5082172 | Y27: 2025-01-21 | Z27: 25.60452 | AC27: 642 | AE27: 2.7330955 | AI27: 642 | AJ27: 16461.586 | AL27: 26.141 | AM27: 21.26 | AN27: Low | AO27: {=_FV(A27,"Currency")} -> USD | AP27: {=_FV(A27,"Exchange")} -> Nasdaq Stock Market | AQ27: {=_FV(A27,"Exchange abbreviation",TRUE)} -> XNAS | AR27: {=_FV(A27,"Instrument type",TRUE)} -> ETF
A28: #VALUE! | B28: MLPB | C28: NO Name | D28: {=_FV(A28,"Last trade time",TRUE)} -> 45824.84 | E28: {=_FV(A28,"Price")} -> 26.0115 | F28: {=_FV(A28,"Change (%)",TRUE)} -> -0.00878 | G28: {=_FV(A28,"Change")} -> -0.2304 | H28: {=_FV(A28,"Open")} -> 26.19 | I28: {=_FV(A28,"Low")} -> 25.92 | J28: {=_FV(A28,"High")} -> 26.19 | K28: {=_FV(A28,"Previous close",TRUE)} -> 26.2419 | M28: {=_FV(A28,"52 week low",TRUE)} -> 22.75 | N28: {=_FV(A28,"52 week high",TRUE)} -> 28.96 | O28: {=_FV(A28,"Volume")} -> 1812 | P28: {=_FV(A28,"Volume average",TRUE)} -> 6635 | Q28: Energy Limited Partnership | S28: UBS | T28: {=_FV(A28,"Expense ratio",TRUE)} -> #VALUE! | U28: {=_FV(A28,"Market cap",TRUE)} -> 76546930000 | V28: 208112720 | W28: 208112720 | Y28: 2015-10-08 | Z28: 25.9645 | AB28: 0.0622 | AC28: 6979 | AE28: 3.9953461 | AF28: 15.727175 | AI28: 6979 | AJ28: 181094.58 | AL28: 28.96 | AM28: 22.75 | AN28: Low | AO28: {=_FV(A28,"Currency")} -> USD | AP28: {=_FV(A28,"Exchange")} -> NYSE Arca | AQ28: {=_FV(A28,"Exchange abbreviation",TRUE)} -> ARCX | AR28: {=_FV(A28,"Instrument type",TRUE)} -> Stock
A29: #VALUE! | B29: IWDL | C29: ETRACS 2x Leveraged US Value Factor TR ETN | D29: {=_FV(A29,"Last trade time",TRUE)} -> 45824.84 | E29: {=_FV(A29,"Price")} -> 40.0263 | F29: {=_FV(A29,"Change (%)",TRUE)} -> 0.014884 | G29: {=_FV(A29,"Change")} -> 0.587 | H29: {=_FV(A29,"Open")} -> 40.05 | I29: {=_FV(A29,"Low")} -> 40.0263 | J29: {=_FV(A29,"High")} -> 40.0501 | K29: {=_FV(A29,"Previous close",TRUE)} -> 39.4393 | M29: {=_FV(A29,"52 week low",TRUE)} -> 30.21 | N29: {=_FV(A29,"52 week high",TRUE)} -> 57.62 | O29: {=_FV(A29,"Volume")} -> 2017 | P29: {=_FV(A29,"Volume average",TRUE)} -> 108 | Q29: Size/Style | R29: Equities - Value Factor | T29: {=_FV(A29,"Expense ratio",TRUE)} -> #VALUE! | U29: {=_FV(A29,"Market cap",TRUE)} -> 76546930000 | AC29: 76 | AN29: Unknown | AO29: {=_FV(A29,"Currency")} -> USD | AP29: {=_FV(A29,"Exchange")} -> NYSE Arca | AQ29: {=_FV(A29,"Exchange abbreviation",TRUE)} -> ARCX | AR29: {=_FV(A29,"Instrument type",TRUE)} -> Stock
A30: #VALUE! | B30: QULL | C30: ETRACS 2x Leveraged MSCI US Quality Factor TR ETN | D30: {=_FV(A30,"Last trade time",TRUE)} -> 45824.84 | E30: {=_FV(A30,"Price")} -> 47.339 | F30: {=_FV(A30,"Change (%)",TRUE)} -> 0.017918 | G30: {=_FV(A30,"Change")} -> 0.8333 | H30: {=_FV(A30,"Open")} -> 47.339 | I30: {=_FV(A30,"Low")} -> 47.339 | J30: {=_FV(A30,"High")} -> 47.339 | K30: {=_FV(A30,"Previous close",TRUE)} -> 46.5057 | M30: {=_FV(A30,"52 week low",TRUE)} -> 33.51 | N30: {=_FV(A30,"52 week high",TRUE)} -> 53.0381 | O30: {=_FV(A30,"Volume")} -> 5 | P30: {=_FV(A30,"Volume average",TRUE)} -> 32 | Q30: Trading--Leveraged Equity | R30: Equities - Quality Factor | S30: UBS | T30: {=_FV(A30,"Expense ratio",TRUE)} -> #VALUE! | U30: {=_FV(A30,"Market cap",TRUE)} -> 76546930000 | V30: 13856700 | W30: 13856700 | Y30: 2021-02-04 | Z30: 47.6938 | AB30: 0 | AC30: 196 | AE30: -0.87630031 | AF30: 7.6544794 | AI30: 196 | AJ30: 9366.0952 | AL30: 53.038 | AM30: 33.51 | AN30: Low | AO30: {=_FV(A30,"Currency")} -> USD | AP30: {=_FV(A30,"Exchange")} -> NYSE Arca | AQ30: {=_FV(A30,"Exchange abbreviation",TRUE)} -> ARCX | AR30: {=_FV(A30,"Instrument type",TRUE)} -> Stock
A31: #VALUE! | B31: AMUB | C31: NO Name | D31: {=_FV(A31,"Last trade time",TRUE)} -> 45824.84 | E31: {=_FV(A31,"Price")} -> 19.1793 | F31: {=_FV(A31,"Change (%)",TRUE)} -> -0.007955 | G31: {=_FV(A31,"Change")} -> -0.1538 | H31: {=_FV(A31,"Open")} -> 19.1793 | I31: {=_FV(A31,"Low")} -> 19.1793 | J31: {=_FV(A31,"High")} -> 19.1793 | K31: {=_FV(A31,"Previous close",TRUE)} -> 19.3331 | M31: {=_FV(A31,"52 week low",TRUE)} -> 16.8574 | N31: {=_FV(A31,"52 week high",TRUE)} -> 20.8771 | O31: {=_FV(A31,"Volume")} -> 5 | P31: {=_FV(A31,"Volume average",TRUE)} -> 2995 | Q31: Energy Limited Partnership | S31: UBS | T31: {=_FV(A31,"Expense ratio",TRUE)} -> #VALUE! | U31: {=_FV(A31,"Market cap",TRUE)} -> 76546930000 | V31: 48549540 | W31: 48549540 | X31: 8.83% | Y31: 2015-10-08 | Z31: 19.1277 | AB31: 0.062800005 | AC31: 2303 | AE31: 3.994512 | AF31: 14.701926 | AI31: 2303 | AJ31: 44002.96 | AL31: 20.877 | AM31: 16.857 | AN31: Low | AO31: {=_FV(A31,"Currency")} -> USD | AP31: {=_FV(A31,"Exchange")} -> NYSE Arca | AQ31: {=_FV(A31,"Exchange abbreviation",TRUE)} -> ARCX | AR31: {=_FV(A31,"Instrument type",TRUE)} -> Stock
A32: #VALUE! | B32: GRN | C32: iPathA Series B Carbon ETN | D32: {=_FV(A32,"Last trade time",TRUE)} -> 45824.84 | E32: {=_FV(A32,"Price")} -> 29.51 | F32: {=_FV(A32,"Change (%)",TRUE)} -> -0.00789 | G32: {=_FV(A32,"Change")} -> -0.2347 | H32: {=_FV(A32,"Open")} -> 29.51 | I32: {=_FV(A32,"Low")} -> 29.51 | J32: {=_FV(A32,"High")} -> 29.51 | K32: {=_FV(A32,"Previous close",TRUE)} -> 29.7447 | M32: {=_FV(A32,"52 week low",TRUE)} -> 23.825 | N32: {=_FV(A32,"52 week high",TRUE)} -> 32.88 | O32: {=_FV(A32,"Volume")} -> 580 | P32: {=_FV(A32,"Volume average",TRUE)} -> 1148 | Q32: Commodities Focused | R32: Commodities - Carbon | S32: iPath | T32: {=_FV(A32,"Expense ratio",TRUE)} -> #VALUE! | U32: {=_FV(A32,"Market cap",TRUE)} -> #VALUE! | V32: 20309600 | W32: 20309600 | Y32: 2019-09-09 | Z32: 28.9432 | AA32: 3.1318347 | AB32: 0 | AC32: 3895 | AE32: 0.49923753 | AF32: 4.3582406 | AI32: 3895 | AJ32: 113069.51 | AL32: 32.88 | AM32: 23.825 | AN32: Low | AO32: {=_FV(A32,"Currency")} -> USD | AP32: {=_FV(A32,"Exchange")} -> NYSE Arca | AQ32: {=_FV(A32,"Exchange abbreviation",TRUE)} -> ARCX | AR32: {=_FV(A32,"Instrument type",TRUE)} -> Stock
A33: #VALUE! | B33: IFED | C33: ETRACS IFED Invest with the Fed TR Index ETN | D33: {=_FV(A33,"Last trade time",TRUE)} -> 45824.84 | E33: {=_FV(A33,"Price")} -> 43.7644 | F33: {=_FV(A33,"Change (%)",TRUE)} -> 0.015401 | G33: {=_FV(A33,"Change")} -> 0.6638 | H33: {=_FV(A33,"Open")} -> 43.7644 | I33: {=_FV(A33,"Low")} -> 43.7644 | J33: {=_FV(A33,"High")} -> 43.7644 | K33: {=_FV(A33,"Previous close",TRUE)} -> 43.1006 | M33: {=_FV(A33,"52 week low",TRUE)} -> 34 | N33: {=_FV(A33,"52 week high",TRUE)} -> 49.7 | O33: {=_FV(A33,"Volume")} -> 10 | P33: {=_FV(A33,"Volume average",TRUE)} -> 451 | Q33: Large Blend | S33: UBS | T33: {=_FV(A33,"Expense ratio",TRUE)} -> #VALUE! | U33: {=_FV(A33,"Market cap",TRUE)} -> 76546930000 | V33: 86366000 | W33: 86366000 | Y33: 2021-09-13 | Z33: 44.2323 | AB33: 0 | AC33: 215 | AE33: 8.5125805 | AF33: 19.407729 | AI33: 215 | AJ33: 9510.7185 | AL33: 49.7 | AM33: 34 | AN33: Low | AO33: {=_FV(A33,"Currency")} -> USD | AP33: {=_FV(A33,"Exchange")} -> NYSE Arca | AQ33: {=_FV(A33,"Exchange abbreviation",TRUE)} -> ARCX | AR33: {=_FV(A33,"Instrument type",TRUE)} -> Stock
A34: #VALUE! | B34: MTUL | C34: ETRACS 2x Leveraged MSCI US Momentum Factor TR ETN | D34: {=_FV(A34,"Last trade time",TRUE)} -> 45824.84 | E34: {=_FV(A34,"Price")} -> 33.5746 | F34: {=_FV(A34,"Change (%)",TRUE)} -> 0.012821 | G34: {=_FV(A34,"Change")} -> 0.425 | H34: {=_FV(A34,"Open")} -> 33.5746 | I34: {=_FV(A34,"Low")} -> 33.5746 | J34: {=_FV(A34,"High")} -> 33.5746 | K34: {=_FV(A34,"Previous close",TRUE)} -> 33.1496 | M34: {=_FV(A34,"52 week low",TRUE)} -> 20.38 | N34: {=_FV(A34,"52 week high",TRUE)} -> 35.4782 | O34: {=_FV(A34,"Volume")} -> 11 | P34: {=_FV(A34,"Volume average",TRUE)} -> 21 | Q34: Trading--Leveraged Equity | R34: Equities - Momentum Factor | S34: UBS | T34: {=_FV(A34,"Expense ratio",TRUE)} -> #VALUE! | U34: {=_FV(A34,"Market cap",TRUE)} -> 76546930000 | V34: 10121400 | W34: 10121400 | Y34: 2021-02-04 | Z34: 34.0553 | AB34: 0 | AC34: 371 | AE34: 13.010613 | AF34: 26.488938 | AI34: 371 | AJ34: 12647.576 | AL34: 35.478 | AM34: 20.38 | AN34: Low | AO34: {=_FV(A34,"Currency")} -> USD | AP34: {=_FV(A34,"Exchange")} -> NYSE Arca | AQ34: {=_FV(A34,"Exchange abbreviation",TRUE)} -> ARCX | AR34: {=_FV(A34,"Instrument type",TRUE)} -> Stock
A35: #VALUE! | B35: SLVO | C35: Ubs Ag Etracs Silver Shares Covered Call ETN Exp 21 Apr 2033 | D35: {=_FV(A35,"Last trade time",TRUE)} -> 45824.876 | E35: {=_FV(A35,"Price")} -> 81.2 | F35: {=_FV(A35,"Change (%)",TRUE)} -> 0.002098 | G35: {=_FV(A35,"Change")} -> 0.17 | H35: {=_FV(A35,"Open")} -> 80.88 | I35: {=_FV(A35,"Low")} -> 80.88 | J35: {=_FV(A35,"High")} -> 81.4 | K35: {=_FV(A35,"Previous close",TRUE)} -> 81.03 | M35: {=_FV(A35,"52 week low",TRUE)} -> 72.6 | N35: {=_FV(A35,"52 week high",TRUE)} -> 86.36 | O35: {=_FV(A35,"Volume")} -> 29762 | P35: {=_FV(A35,"Volume average",TRUE)} -> 45169 | Q35: Commodities Focused | R35: Commodities - Silver | S35: UBS AG | T35: {=_FV(A35,"Expense ratio",TRUE)} -> #VALUE! | U35: {=_FV(A35,"Market cap",TRUE)} -> 76546930000 | V35: 191519984 | W35: 191519984 | Y35: 2013-04-15 | Z35: 80.6223 | AB35: 0.2317 | AC35: 38738 | AE35: 19.227609 | AF35: 22.670746 | AI35: 38738 | AJ35: 3123251.2 | AL35: 86.36 | AM35: 72.6 | AN35: Medium | AO35: {=_FV(A35,"Currency")} -> USD | AP35: {=_FV(A35,"Exchange")} -> Nasdaq Stock Market | AQ35: {=_FV(A35,"Exchange abbreviation",TRUE)} -> XNAS | AR35: {=_FV(A35,"Instrument type",TRUE)} -> Stock
A36: #VALUE! | B36: BDCZ | C36: NO Name | D36: {=_FV(A36,"Last trade time",TRUE)} -> 45824.84 | E36: {=_FV(A36,"Price")} -> 18.0452 | F36: {=_FV(A36,"Change (%)",TRUE)} -> -0.007917 | G36: {=_FV(A36,"Change")} -> -0.144 | H36: {=_FV(A36,"Open")} -> 18.15 | I36: {=_FV(A36,"Low")} -> 18.0452 | J36: {=_FV(A36,"High")} -> 18.15 | K36: {=_FV(A36,"Previous close",TRUE)} -> 18.1892 | M36: {=_FV(A36,"52 week low",TRUE)} -> 16.31 | N36: {=_FV(A36,"52 week high",TRUE)} -> 20.4154 | O36: {=_FV(A36,"Volume")} -> 276 | P36: {=_FV(A36,"Volume average",TRUE)} -> 876 | Q36: Financial | S36: UBS | T36: {=_FV(A36,"Expense ratio",TRUE)} -> #VALUE! | U36: {=_FV(A36,"Market cap",TRUE)} -> 76546930000 | V36: 19551040 | W36: 19551040 | X36: -7.73% | Y36: 2015-10-08 | Z36: 18.2797 | AB36: 0.098500006 | AC36: 3700 | AE36: -1.1192863 | AF36: 2.3906965 | AI36: 3700 | AJ36: 67650.06 | AL36: 20.415 | AM36: 16.31 | AN36: Low | AO36: {=_FV(A36,"Currency")} -> USD | AP36: {=_FV(A36,"Exchange")} -> NYSE Arca | AQ36: {=_FV(A36,"Exchange abbreviation",TRUE)} -> ARCX | AR36: {=_FV(A36,"Instrument type",TRUE)} -> Stock
A37: #VALUE! | B37: BDCX | C37: ETRACS Quarterly Pay 1.5x Leveraged MarketVector BDC Liquid In | D37: {=_FV(A37,"Last trade time",TRUE)} -> 45824.84 | E37: {=_FV(A37,"Price")} -> 28 | F37: {=_FV(A37,"Change (%)",TRUE)} -> -0.011341 | G37: {=_FV(A37,"Change")} -> -0.3212 | H37: {=_FV(A37,"Open")} -> 28.22 | I37: {=_FV(A37,"Low")} -> 28 | J37: {=_FV(A37,"High")} -> 28.36 | K37: {=_FV(A37,"Previous close",TRUE)} -> 28.3212 | M37: {=_FV(A37,"52 week low",TRUE)} -> 23.9495 | N37: {=_FV(A37,"52 week high",TRUE)} -> 35.98 | O37: {=_FV(A37,"Volume")} -> 4142 | P37: {=_FV(A37,"Volume average",TRUE)} -> 2379 | Q37: Trading--Leveraged Equity | S37: UBS | T37: {=_FV(A37,"Expense ratio",TRUE)} -> #VALUE! | U37: {=_FV(A37,"Market cap",TRUE)} -> 76546930000 | V37: 11418320 | W37: 11418320 | X37: -16.71% | Y37: 2020-06-01 | Z37: 28.5505 | AB37: 0.1733 | AC37: 2971 | AE37: -4.2221448 | AF37: -0.80989501 | AI37: 2971 | AJ37: 84833.934 | AL37: 35.98 | AM37: 23.95 | AN37: Low | AO37: {=_FV(A37,"Currency")} -> USD | AP37: {=_FV(A37,"Exchange")} -> NYSE Arca | AQ37: {=_FV(A37,"Exchange abbreviation",TRUE)} -> ARCX | AR37: {=_FV(A37,"Instrument type",TRUE)} -> Stock
A38: #VALUE! | B38: MLPR | C38: ETRACS Quarterly Pay 1.5X Leveraged Alerian MLP Index ETN | D38: {=_FV(A38,"Last trade time",TRUE)} -> 45824.84 | E38: {=_FV(A38,"Price")} -> 60.9326 | F38: {=_FV(A38,"Change (%)",TRUE)} -> -0.011545 | G38: {=_FV(A38,"Change")} -> -0.7117 | H38: {=_FV(A38,"Open")} -> 60.9326 | I38: {=_FV(A38,"Low")} -> 60.9326 | J38: {=_FV(A38,"High")} -> 60.9326 | K38: {=_FV(A38,"Previous close",TRUE)} -> 61.6443 | M38: {=_FV(A38,"52 week low",TRUE)} -> 50.7179 | N38: {=_FV(A38,"52 week high",TRUE)} -> 73.37 | O38: {=_FV(A38,"Volume")} -> 64 | P38: {=_FV(A38,"Volume average",TRUE)} -> 1078 | Q38: Trading--Leveraged Equity | S38: UBS | T38: {=_FV(A38,"Expense ratio",TRUE)} -> #VALUE! | U38: {=_FV(A38,"Market cap",TRUE)} -> 76546930000 | V38: 17595480 | W38: 17595480 | Y38: 2020-06-01 | Z38: 60.7127 | AB38: 0.10439999 | AC38: 1330 | AE38: 4.3829776 | AF38: 18.479675 | AI38: 1330 | AJ38: 80682.322 | AL38: 73.37 | AM38: 50.718 | AN38: Low | AO38: {=_FV(A38,"Currency")} -> USD | AP38: {=_FV(A38,"Exchange")} -> NYSE Arca | AQ38: {=_FV(A38,"Exchange abbreviation",TRUE)} -> ARCX | AR38: {=_FV(A38,"Instrument type",TRUE)} -> Stock
A39: #VALUE! | B39: AMJB | C39: JPMorgan Chase & Co. Alerian MLP Index ETNs due January 28 20 | D39: {=_FV(A39,"Last trade time",TRUE)} -> 45824.84 | E39: {=_FV(A39,"Price")} -> 30.54 | F39: {=_FV(A39,"Change (%)",TRUE)} -> -0.007475 | G39: {=_FV(A39,"Change")} -> -0.23 | H39: {=_FV(A39,"Open")} -> 30.77 | I39: {=_FV(A39,"Low")} -> 30.3 | J39: {=_FV(A39,"High")} -> 30.81 | K39: {=_FV(A39,"Previous close",TRUE)} -> 30.77 | M39: {=_FV(A39,"52 week low",TRUE)} -> 26.645 | N39: {=_FV(A39,"52 week high",TRUE)} -> 33.4 | O39: {=_FV(A39,"Volume")} -> 24878 | P39: {=_FV(A39,"Volume average",TRUE)} -> 40063 | Q39: Energy Limited Partnership | S39: JPMorgan Chase & Co | T39: {=_FV(A39,"Expense ratio",TRUE)} -> #VALUE! | U39: {=_FV(A39,"Market cap",TRUE)} -> 736321100000 | V39: 724508288 | W39: 724508288 | X39: 8.83% | Y39: 2024-01-25 | Z39: 30.45 | AB39: 0.0625 | AC39: 56019 | AE39: 3.8842622 | AF39: 14.656205 | AI39: 56019 | AJ39: 1705778.6 | AL39: 33.4 | AM39: 26.645 | AN39: Medium | AO39: {=_FV(A39,"Currency")} -> USD | AP39: {=_FV(A39,"Exchange")} -> NYSE Arca | AQ39: {=_FV(A39,"Exchange abbreviation",TRUE)} -> ARCX | AR39: {=_FV(A39,"Instrument type",TRUE)} -> Stock
A40: #VALUE! | B40: SMHB | C40: NO Name | D40: {=_FV(A40,"Last trade time",TRUE)} -> 45824.934 | E40: {=_FV(A40,"Price")} -> 4.43 | F40: {=_FV(A40,"Change (%)",TRUE)} -> 0.026413 | G40: {=_FV(A40,"Change")} -> 0.114 | H40: {=_FV(A40,"Open")} -> 4.4004 | I40: {=_FV(A40,"Low")} -> 4.38 | J40: {=_FV(A40,"High")} -> 4.4432 | K40: {=_FV(A40,"Previous close",TRUE)} -> 4.316 | M40: {=_FV(A40,"52 week low",TRUE)} -> 3.165 | N40: {=_FV(A40,"52 week high",TRUE)} -> 6.66 | O40: {=_FV(A40,"Volume")} -> 16213 | P40: {=_FV(A40,"Volume average",TRUE)} -> 31655 | Q40: Other | T40: {=_FV(A40,"Expense ratio",TRUE)} -> #VALUE! | U40: {=_FV(A40,"Market cap",TRUE)} -> 76546930000 | AC40: 34677 | AN40: Unknown | AO40: {=_FV(A40,"Currency")} -> USD | AP40: {=_FV(A40,"Exchange")} -> NYSE Arca | AQ40: {=_FV(A40,"Exchange abbreviation",TRUE)} -> ARCX | AR40: {=_FV(A40,"Instrument type",TRUE)} -> Stock
...

Sheet ETFs Filtered
A1: Names | B1: Ticker | C1: Asset Class | D1: Sector | E1: Sub Sector | F1: Sub Sub Sector | G1: Strategy Description | H1: Ticker | I1: Last Update | J1: Last Price | K1: 1d% | L1: Net Change | M1: Open | N1: Lo | O1: Hi | P1: Prev Cls | Q1: 52W Lo | R1: 52W Hi | S1: Volume | T1: Avg Volume | U1: Avg $ volume | V1: Expense Ratio (net) | W1: Market Cap
A2: AltShares Merger Arbitrage ETF | B2: ARB | C2: Alternatives | D2: Hedge Fund Replication | Y2: =IF(B2=B1,"XXX","")
A3: PMV Adaptive Risk Parity ETF | B3: ARP | C3: Alternatives | D3: Risk parity | G3: Alternative risk premia multi-factor | H3: #VALUE! | I3: {=_FV(H3,"Last trade time",TRUE)} -> 45824.84 | J3: {=_FV(H3,"Price")} -> 28.46 | K3: {=_FV(H3,"Change (%)",TRUE)} -> 0.0004922 | L3: {=_FV(H3,"Change")} -> 0.014 | M3: {=_FV(H3,"Open")} -> 28.53 | N3: {=_FV(H3,"Low")} -> 28.45 | O3: {=_FV(H3,"High")} -> 28.53 | P3: {=_FV(H3,"Previous close",TRUE)} -> 28.446 | Q3: {=_FV(H3,"52 week low",TRUE)} -> 26.3 | R3: {=_FV(H3,"52 week high",TRUE)} -> 30.22 | S3: {=_FV(H3,"Volume")} -> 12017 | T3: {=_FV(H3,"Volume average",TRUE)} -> 4632 | V3: {=_FV(H3,"Expense ratio",TRUE)} -> 0.0147 | W3: {=_FV(H3,"Market cap",TRUE)} -> 40790904 | Y3: =IF(B3=B2,"XXX","")
A4: VanEck BDC Income ETF | B4: BIZD | C4: Alternatives | D4: Business Development Company | E4: venture capital | G4: buys shares of firms that in turn invest in the debt and equity of mid-sized private firms | H4: #VALUE! | I4: {=_FV(H4,"Last trade time",TRUE)} -> 45824.923 | J4: {=_FV(H4,"Price")} -> 16.05 | K4: {=_FV(H4,"Change (%)",TRUE)} -> -0.004342 | L4: {=_FV(H4,"Change")} -> -0.07 | M4: {=_FV(H4,"Open")} -> 16.15 | N4: {=_FV(H4,"Low")} -> 15.94 | O4: {=_FV(H4,"High")} -> 16.28 | P4: {=_FV(H4,"Previous close",TRUE)} -> 16.12 | Q4: {=_FV(H4,"52 week low",TRUE)} -> 13.5 | R4: {=_FV(H4,"52 week high",TRUE)} -> 17.8565 | S4: {=_FV(H4,"Volume")} -> 1010713 | T4: {=_FV(H4,"Volume average",TRUE)} -> 959469 | V4: {=_FV(H4,"Expense ratio",TRUE)} -> 0.1333 | W4: {=_FV(H4,"Market cap",TRUE)} -> 1.5677835e+09 | Y4: =IF(B4=B3,"XXX","")
A5: AGF U.S. Market Neutral Anti-Beta ETF | B5: BTAL | C5: Alternatives | D5: Equity long short tactical | Y5: =IF(B5=B4,"XXX","")
A6: Blackstone Alternative Multi-Strategy Fund;D | B6: BXMDX | C6: Alternatives | D6: Hedge Fund Replication | G6: BlackRock Multi-Asset Income Fund | H6: #VALUE! | I6: {=_FV(H6,"Last trade time",TRUE)} -> 45824.94 | J6: {=_FV(H6,"Price")} -> 10.84 | K6: {=_FV(H6,"Change (%)",TRUE)} -> -0.0009217 | L6: {=_FV(H6,"Change")} -> -0.01 | M6: {=_FV(H6,"Open")} -> #VALUE! | N6: {=_FV(H6,"Low")} -> #VALUE! | O6: {=_FV(H6,"High")} -> #VALUE! | P6: {=_FV(H6,"Previous close",TRUE)} -> 10.85 | Q6: {=_FV(H6,"52 week low",TRUE)} -> #VALUE! | R6: {=_FV(H6,"52 week high",TRUE)} -> #VALUE! | S6: {=_FV(H6,"Volume")} -> #VALUE! | T6: {=_FV(H6,"Volume average",TRUE)} -> #VALUE! | V6: {=_FV(H6,"Expense ratio",TRUE)} -> 0.0548 | W6: {=_FV(H6,"Market cap",TRUE)} -> #VALUE! | Y6: =IF(B6=B5,"XXX","")
A7: Clough Hedged Equity ETF | B7: CBLS | C7: Alternatives | D7: Equity long short tactical | G7: Attempts to replicate merger arbitrage strategies | H7: #VALUE! | I7: {=_FV(H7,"Last trade time",TRUE)} -> 45824.84 | J7: {=_FV(H7,"Price")} -> 28.373 | K7: {=_FV(H7,"Change (%)",TRUE)} -> 0.00258 | L7: {=_FV(H7,"Change")} -> 0.073 | M7: {=_FV(H7,"Open")} -> 28.35 | N7: {=_FV(H7,"Low")} -> 28.35 | O7: {=_FV(H7,"High")} -> 28.43 | P7: {=_FV(H7,"Previous close",TRUE)} -> 28.3 | Q7: {=_FV(H7,"52 week low",TRUE)} -> 24.1469 | R7: {=_FV(H7,"52 week high",TRUE)} -> 28.83 | S7: {=_FV(H7,"Volume")} -> 28133 | T7: {=_FV(H7,"Volume average",TRUE)} -> 11329 | V7: {=_FV(H7,"Expense ratio",TRUE)} -> 0.0259 | W7: {=_FV(H7,"Market cap",TRUE)} -> 42597655 | Y7: =IF(B7=B6,"XXX","")
A8: Simplify Managed Futures Strategy ETF | B8: CTA | C8: Alternatives | D8: Managed Futures | G8: Managed futures and trend following strategies | H8: #VALUE! | I8: {=_FV(H8,"Last trade time",TRUE)} -> 45824.843 | J8: {=_FV(H8,"Price")} -> 28.3 | K8: {=_FV(H8,"Change (%)",TRUE)} -> 0.013247 | L8: {=_FV(H8,"Change")} -> 0.37 | M8: {=_FV(H8,"Open")} -> 28.03 | N8: {=_FV(H8,"Low")} -> 28.02 | O8: {=_FV(H8,"High")} -> 28.3 | P8: {=_FV(H8,"Previous close",TRUE)} -> 27.93 | Q8: {=_FV(H8,"52 week low",TRUE)} -> 25.6601 | R8: {=_FV(H8,"52 week high",TRUE)} -> 30.213 | S8: {=_FV(H8,"Volume")} -> 254045 | T8: {=_FV(H8,"Volume average",TRUE)} -> 447032 | V8: {=_FV(H8,"Expense ratio",TRUE)} -> 0.0076 | W8: {=_FV(H8,"Market cap",TRUE)} -> 1.0721217e+09 | Y8: =IF(B8=B7,"XXX","")
A9: Simplify Managed Futures Strategy ETF | B9: CTA | C9: Alternatives | D9: Managed Future | Y9: =IF(B9=B8,"XXX","") -> XXX
A10: iMGP DBi Managed Futures Strategy ETF | B10: DBMF | C10: Alternatives | D10: Managed Futures | G10: Managed futures multi-strategy approach | H10: #VALUE! | I10: {=_FV(H10,"Last trade time",TRUE)} -> 45824.918 | J10: {=_FV(H10,"Price")} -> 25.63 | K10: {=_FV(H10,"Change (%)",TRUE)} -> -0.002336 | L10: {=_FV(H10,"Change")} -> -0.06 | M10: {=_FV(H10,"Open")} -> 25.72 | N10: {=_FV(H10,"Low")} -> 25.625 | O10: {=_FV(H10,"High")} -> 25.72 | P10: {=_FV(H10,"Previous close",TRUE)} -> 25.69 | Q10: {=_FV(H10,"52 week low",TRUE)} -> 24.5201 | R10: {=_FV(H10,"52 week high",TRUE)} -> 30.6299 | S10: {=_FV(H10,"Volume")} -> 483001 | T10: {=_FV(H10,"Volume average",TRUE)} -> 354904 | V10: {=_FV(H10,"Expense ratio",TRUE)} -> 0.0085 | W10: {=_FV(H10,"Market cap",TRUE)} -> 1.193e+09 | Y10: =IF(B10=B9,"XXX","")
A11: iMGP DBi Managed Futures Strategy ETF | B11: DBMF | C11: Alternatives | D11: Managed Future | Y11: =IF(B11=B10,"XXX","") -> XXX
A12: First Trust Managed Futures Strategy Fund | B12: FMF | C12: Alternatives | D12: Managed Futures | G12: Multi-manager alternative strategies | H12: #VALUE! | I12: {=_FV(H12,"Last trade time",TRUE)} -> 45824.84 | J12: {=_FV(H12,"Price")} -> 45.9935 | K12: {=_FV(H12,"Change (%)",TRUE)} -> 0.009028 | L12: {=_FV(H12,"Change")} -> 0.4115 | M12: {=_FV(H12,"Open")} -> 45.63 | N12: {=_FV(H12,"Low")} -> 45.5 | O12: {=_FV(H12,"High")} -> 46.16 | P12: {=_FV(H12,"Previous close",TRUE)} -> 45.582 | Q12: {=_FV(H12,"52 week low",TRUE)} -> 44.0788 | R12: {=_FV(H12,"52 week high",TRUE)} -> 49.9099 | S12: {=_FV(H12,"Volume")} -> 29934 | T12: {=_FV(H12,"Volume average",TRUE)} -> 20878 | V12: {=_FV(H12,"Expense ratio",TRUE)} -> 0.0095 | W12: {=_FV(H12,"Market cap",TRUE)} -> 1.5317759e+08 | Y12: =IF(B12=B11,"XXX","")
A13: Formidable ETF | B13: FORH | C13: Alternatives | D13: Hedge Fund Replication | G13: Long-short equity strategy targeting value stocks | H13: #VALUE! | I13: {=_FV(H13,"Last trade time",TRUE)} -> 45824.84 | J13: {=_FV(H13,"Price")} -> 22.7949 | K13: {=_FV(H13,"Change (%)",TRUE)} -> -0.00218 | L13: {=_FV(H13,"Change")} -> -0.0498 | M13: {=_FV(H13,"Open")} -> 22.7901 | N13: {=_FV(H13,"Low")} -> 22.7901 | O13: {=_FV(H13,"High")} -> 22.7949 | P13: {=_FV(H13,"Previous close",TRUE)} -> 22.8447 | Q13: {=_FV(H13,"52 week low",TRUE)} -> 19.13 | R13: {=_FV(H13,"52 week high",TRUE)} -> 23.8 | S13: {=_FV(H13,"Volume")} -> 291 | T13: {=_FV(H13,"Volume average",TRUE)} -> 2526 | V13: {=_FV(H13,"Expense ratio",TRUE)} -> 0.0119 | W13: {=_FV(H13,"Market cap",TRUE)} -> 19625360 | Y13: =IF(B13=B12,"XXX","")
A14: Greenlight Capital Re, Ltd. | B14: GLRE | C14: Alternatives | D14: Hedge Fund Replication | Y14: =IF(B14=B13,"XXX","")
A15: ProShares Hedge Replication ETF | B15: HDG | C15: Alternatives | D15: Hedge Fund Replication | G15: Currency hedged international equity exposure | H15: #VALUE! | I15: {=_FV(H15,"Last trade time",TRUE)} -> 45824.84 | J15: {=_FV(H15,"Price")} -> 49.5079 | K15: {=_FV(H15,"Change (%)",TRUE)} -> 0.001704 | L15: {=_FV(H15,"Change")} -> 0.0842 | M15: {=_FV(H15,"Open")} -> 49.44 | N15: {=_FV(H15,"Low")} -> 49.44 | O15: {=_FV(H15,"High")} -> 49.5079 | P15: {=_FV(H15,"Previous close",TRUE)} -> 49.4237 | Q15: {=_FV(H15,"52 week low",TRUE)} -> 46.28 | R15: {=_FV(H15,"52 week high",TRUE)} -> 50.6981 | S15: {=_FV(H15,"Volume")} -> 442 | T15: {=_FV(H15,"Volume average",TRUE)} -> 844 | V15: {=_FV(H15,"Expense ratio",TRUE)} -> 0.0095 | W15: {=_FV(H15,"Market cap",TRUE)} -> 24418944 | Y15: =IF(B15=B14,"XXX","")
A16: Int. Hedged Equity | B16: HEDJ | C16: Alternatives | D16: Equity long short tactical | G16: Euro hedged European equity index | H16: #VALUE! | I16: {=_FV(H16,"Last trade time",TRUE)} -> 45824.84 | J16: {=_FV(H16,"Price")} -> 49.03 | K16: {=_FV(H16,"Change (%)",TRUE)} -> 0.009471 | L16: {=_FV(H16,"Change")} -> 0.46 | M16: {=_FV(H16,"Open")} -> 48.85 | N16: {=_FV(H16,"Low")} -> 48.85 | O16: {=_FV(H16,"High")} -> 49.23 | P16: {=_FV(H16,"Previous close",TRUE)} -> 48.57 | Q16: {=_FV(H16,"52 week low",TRUE)} -> 40.83 | R16: {=_FV(H16,"52 week high",TRUE)} -> 50.78 | S16: {=_FV(H16,"Volume")} -> 61815 | T16: {=_FV(H16,"Volume average",TRUE)} -> 152308 | V16: {=_FV(H16,"Expense ratio",TRUE)} -> 0.0058 | W16: {=_FV(H16,"Market cap",TRUE)} -> 1.7761079e+09 | Y16: =IF(B16=B15,"XXX","")
A17: Unlimited HFND Multi-Strategy Return Tracker ETF | B17: HFND | C17: Alternatives | D17: Hedge Fund Replication | Y17: =IF(B17=B16,"XXX","")
A18: HERCULES CAPITAL, INC. (XNYS:HTGC) | B18: HTGC | C18: Alternatives | D18: Business Development Company | E18: Broad Markets | G18: specializing in providing private equity, venture debt, and growth capital to privately held venture capital-backed companies at all stages of development | H18: #VALUE! | I18: {=_FV(H18,"Last trade time",TRUE)} -> 45824.855 | J18: {=_FV(H18,"Price")} -> 17.87 | K18: {=_FV(H18,"Change (%)",TRUE)} -> -0.006118 | L18: {=_FV(H18,"Change")} -> -0.11 | M18: {=_FV(H18,"Open")} -> 18.12 | N18: {=_FV(H18,"Low")} -> 17.8335 | O18: {=_FV(H18,"High")} -> 18.21 | P18: {=_FV(H18,"Previous close",TRUE)} -> 17.98 | Q18: {=_FV(H18,"52 week low",TRUE)} -> 15.65 | R18: {=_FV(H18,"52 week high",TRUE)} -> 22.04 | S18: {=_FV(H18,"Volume")} -> 856414 | T18: {=_FV(H18,"Volume average",TRUE)} -> 1358314 | V18: {=_FV(H18,"Expense ratio",TRUE)} -> #VALUE! | W18: {=_FV(H18,"Market cap",TRUE)} -> 3134864407 | Y18: =IF(B18=B17,"XXX","")
A19: Capitol Series Trust Hull Tactical US ETF | B19: HTUS | C19: Alternatives | D19: Equity long short tactical | G19: Hedged equity strategy with downside protection | H19: #VALUE! | I19: {=_FV(H19,"Last trade time",TRUE)} -> 45824.84 | J19: {=_FV(H19,"Price")} -> 38.7693 | K19: {=_FV(H19,"Change (%)",TRUE)} -> 0.002309 | L19: {=_FV(H19,"Change")} -> 0.0893 | M19: {=_FV(H19,"Open")} -> 38.89 | N19: {=_FV(H19,"Low")} -> 38.7693 | O19: {=_FV(H19,"High")} -> 38.89 | P19: {=_FV(H19,"Previous close",TRUE)} -> 38.68 | Q19: {=_FV(H19,"52 week low",TRUE)} -> 27.5 | R19: {=_FV(H19,"52 week high",TRUE)} -> 47.73 | S19: {=_FV(H19,"Volume")} -> 3601 | T19: {=_FV(H19,"Volume average",TRUE)} -> 12667 | V19: {=_FV(H19,"Expense ratio",TRUE)} -> 0.0096 | W19: {=_FV(H19,"Market cap",TRUE)} -> 1.1863005e+08 | Y19: =IF(B19=B18,"XXX","")
A20: Vest 2 Year Interest Rate Hedge ETF | B20: HYKE | C20: Alternatives | D20: Interest Rate and Inflation Hedge | G20: High yield corporate bond ETF | H20: #VALUE! | I20: {=_FV(H20,"Last trade time",TRUE)} -> 45824.84 | J20: {=_FV(H20,"Price")} -> 25.8967 | K20: {=_FV(H20,"Change (%)",TRUE)} -> 0.004722 | L20: {=_FV(H20,"Change")} -> 0.1217 | M20: {=_FV(H20,"Open")} -> 25.8967 | N20: {=_FV(H20,"Low")} -> 25.8967 | O20: {=_FV(H20,"High")} -> 25.8967 | P20: {=_FV(H20,"Previous close",TRUE)} -> 25.775 | Q20: {=_FV(H20,"52 week low",TRUE)} -> 23.6494 | R20: {=_FV(H20,"52 week high",TRUE)} -> 29.8452 | S20: {=_FV(H20,"Volume")} -> 5 | T20: {=_FV(H20,"Volume average",TRUE)} -> 4 | V20: {=_FV(H20,"Expense ratio",TRUE)} -> 0.009 | W20: {=_FV(H20,"Market cap",TRUE)} -> 1271182.5 | Y20: =IF(B20=B19,"XXX","")
A21: Icahn Enterprises L.P. | B21: IEP | C21: Alternatives | D21: Hedge Fund Replication | Y21: =IF(B21=B20,"XXX","")
A22: KFA Mount Lucas Managed Futures Index Strategy ETF | B22: KMLM | C22: Alternatives | D22: Managed Futures | G22: Alternative risk premia capture | H22: #VALUE! | I22: {=_FV(H22,"Last trade time",TRUE)} -> 45824.84 | J22: {=_FV(H22,"Price")} -> 26.01 | K22: {=_FV(H22,"Change (%)",TRUE)} -> -0.002684 | L22: {=_FV(H22,"Change")} -> -0.07 | M22: {=_FV(H22,"Open")} -> 26.12 | N22: {=_FV(H22,"Low")} -> 26.01 | O22: {=_FV(H22,"High")} -> 26.3 | P22: {=_FV(H22,"Previous close",TRUE)} -> 26.08 | Q22: {=_FV(H22,"52 week low",TRUE)} -> 25.91 | R22: {=_FV(H22,"52 week high",TRUE)} -> 30.19 | S22: {=_FV(H22,"Volume")} -> 18115 | T22: {=_FV(H22,"Volume average",TRUE)} -> 70652 | V22: {=_FV(H22,"Expense ratio",TRUE)} -> 0.009 | W22: {=_FV(H22,"Market cap",TRUE)} -> 1.9256577e+08 | Y22: =IF(B22=B21,"XXX","")
A23: First Trust Multi-Strategy Alternative ETF | B23: LALT | C23: Alternatives | D23: Hedge Fund Replication | Y23: =IF(B23=B22,"XXX","")
A24: ProShares Global Listed Private Equity ETF | B24: PEX | C24: Alternatives | D24: Business Development Company | G24: ProShares Global Listed Private Equity | H24: #VALUE! | I24: {=_FV(H24,"Last trade time",TRUE)} -> 45824.863 | J24: {=_FV(H24,"Price")} -> 27.6575 | K24: {=_FV(H24,"Change (%)",TRUE)} -> -0.003333 | L24: {=_FV(H24,"Change")} -> -0.0925 | M24: {=_FV(H24,"Open")} -> 28.14 | N24: {=_FV(H24,"Low")} -> 27.6575 | O24: {=_FV(H24,"High")} -> 28.14 | P24: {=_FV(H24,"Previous close",TRUE)} -> 27.75 | Q24: {=_FV(H24,"52 week low",TRUE)} -> 23.46 | R24: {=_FV(H24,"52 week high",TRUE)} -> 30.34 | S24: {=_FV(H24,"Volume")} -> 1523 | T24: {=_FV(H24,"Volume average",TRUE)} -> 3291 | V24: {=_FV(H24,"Expense ratio",TRUE)} -> 0.006 | W24: {=_FV(H24,"Market cap",TRUE)} -> 13538777 | Y24: =IF(B24=B23,"XXX","")
A25: Simplify Interest Rate Hedge ETF | B25: PFIX | C25: Alternatives | D25: Interest Rate and Inflation Hedge | G25: Inflation-protected securities with variable duration | H25: #VALUE! | I25: {=_FV(H25,"Last trade time",TRUE)} -> 45824.841 | J25: {=_FV(H25,"Price")} -> 59.5 | K25: {=_FV(H25,"Change (%)",TRUE)} -> 0.048828 | L25: {=_FV(H25,"Change")} -> 2.77 | M25: {=_FV(H25,"Open")} -> 57.12 | N25: {=_FV(H25,"Low")} -> 56.65 | O25: {=_FV(H25,"High")} -> 59.5 | P25: {=_FV(H25,"Previous close",TRUE)} -> 56.73 | Q25: {=_FV(H25,"52 week low",TRUE)} -> 37 | R25: {=_FV(H25,"52 week high",TRUE)} -> 65.1521 | S25: {=_FV(H25,"Volume")} -> 269712 | T25: {=_FV(H25,"Volume average",TRUE)} -> 177127 | V25: {=_FV(H25,"Expense ratio",TRUE)} -> 0.005 | W25: {=_FV(H25,"Market cap",TRUE)} -> 1.6781209e+08 | Y25: =IF(B25=B24,"XXX","")
A26: Pershing Square Holdings Ltd. | B26: PSH | C26: Alternatives | D26: Hedge Fund Replication | Y26: =IF(B26=B25,"XXX","")
A27: NYLI Hedge Multi-Strategy Tracker ETF | B27: QAI | C27: Alternatives | D27: Hedge Fund Replication | G27: Multi-alternative strategies replication | H27: #VALUE! | I27: {=_FV(H27,"Last trade time",TRUE)} -> 45824.84 | J27: {=_FV(H27,"Price")} -> 32.09 | K27: {=_FV(H27,"Change (%)",TRUE)} -> 0.005011 | L27: {=_FV(H27,"Change")} -> 0.16 | M27: {=_FV(H27,"Open")} -> 32.01 | N27: {=_FV(H27,"Low")} -> 32.01 | O27: {=_FV(H27,"High")} -> 32.1 | P27: {=_FV(H27,"Previous close",TRUE)} -> 31.93 | Q27: {=_FV(H27,"52 week low",TRUE)} -> 29.57 | R27: {=_FV(H27,"52 week high",TRUE)} -> 32.7959 | S27: {=_FV(H27,"Volume")} -> 324450 | T27: {=_FV(H27,"Volume average",TRUE)} -> 65537 | V27: {=_FV(H27,"Expense ratio",TRUE)} -> 0.0091 | W27: {=_FV(H27,"Market cap",TRUE)} -> 6.9695524e+08 | Y27: =IF(B27=B26,"XXX","")
A28: Global X Interest Rate Hedge ETF | B28: RATE | C28: Alternatives | D28: Interest Rate and Inflation Hedge | G28: Interest rate hedged high yield bonds | H28: #VALUE! | I28: {=_FV(H28,"Last trade time",TRUE)} -> 45824.84 | J28: {=_FV(H28,"Price")} -> 18.5653 | K28: {=_FV(H28,"Change (%)",TRUE)} -> 0.004322 | L28: {=_FV(H28,"Change")} -> 0.0799 | M28: {=_FV(H28,"Open")} -> 18.5653 | N28: {=_FV(H28,"Low")} -> 18.5653 | O28: {=_FV(H28,"High")} -> 18.5653 | P28: {=_FV(H28,"Previous close",TRUE)} -> 18.4854 | Q28: {=_FV(H28,"52 week low",TRUE)} -> 17.1192 | R28: {=_FV(H28,"52 week high",TRUE)} -> 21.62 | S28: {=_FV(H28,"Volume")} -> 266 | T28: {=_FV(H28,"Volume average",TRUE)} -> 1243 | V28: {=_FV(H28,"Expense ratio",TRUE)} -> 0.0045 | W28: {=_FV(H28,"Market cap",TRUE)} -> 2600296.1 | Y28: =IF(B28=B27,"XXX","")
